Workbook

Sheet Resumen_Ejecutivo
B2: PRESUPUESTO Y MODELO FINANCIERO INTEGRAL — TORRE SATORI PMS
B3: Sistema de Gestión Hotelera · Proyecto Integrador II · Universidad Icesi (2026-2) · Moneda: COP / TRM $4.150
B4: Convención visual: Fondo amarillo tenue = Parámetro o dato editable | Fondo blanco/gris = Cálculo automático con fórmula | Fondo rojo tenue = Pendiente de cotización/validar
B6: A. IDENTIFICACIÓN DEL PROYECTO Y ALCANCE PRESUPUESTADO
B7: Proyecto | C7: Torre Satori PMS: Property Management System para hotel familiar con motor de reservas y chatbot inteligente
B8: Organización / Cliente | C8: Hotel Torre Satori (Sevilla, Valle del Cauca) · Propietario / Stakeholder principal
B9: Equipo de Desarrollo | C9: Juan José Arias Gallego (Product Owner) · Esteban Guarín Valencia (Scrum Master & Backend) · Juan Felipe Garzón Trejos (Frontend & n8n)
B10: Solución Tecnológica | C10: Monolito modular hexagonal en Java 21 / Spring Boot 3.3, Redis 7 (locks 15 min), PostgreSQL 16 (EXCLUDE GIST), n8n (WhatsApp Meta Cloud API + Google Gemini Flash Lite) y web en React/Vite
B11: Alcance Presupuestado (MVP) | C11: 150 Story Points de desarrollo en 5 Sprints (10 semanas) + 38 horas de puesta en marcha, parametrización y capacitación presencial en Sevilla (Fases 1 a 11 EDT)
B12: Fuera de Alcance Inicial | C12: Arquitectura de microservicios distribuidos, operación multi-hotel/multi-tenant simultánea, motor de reservas web con pasarela directa (idea a futuro)
B13: Estado Actual del Trabajo | C13: Flujo V8 n8n activo (80 nodos), 5 migraciones Flyway validadas, reserva guiada, abono parcial 50%/100%, liquidación de saldo, cancelación RN-03, reseñas con Google y asistente IA autónomo
B14: Fecha de Corte y Versión | C14: Octubre de 2026 · Versión 3.0 Definitiva basada en la arquitectura real Spring Boot + Redis + PostgreSQL + n8n
B16: A.1 PARÁMETROS ECONÓMICOS, SUPUESTOS Y TARIFAS DE REFERENCIA
B17: Grupo | C17: Parámetro / Supuesto | E17: Valor | F17: Unidad | G17: Estado | H17: Fundamento y Origen del Dato
B18: Equipo | C18: Integrantes del equipo de desarrollo | E18: 3 | F18: personas | G18: Confirmado | H18: Esteban Guarín, Juan José Arias y Juan Felipe Garzón
B19: Equipo | C19: Dedicación semanal por integrante | E19: 20 | F19: h/semana | G19: Confirmado | H19: Compromiso académico en Proyecto Integrador II
B20: Equipo | C20: Duración del desarrollo del proyecto | E20: 10 | F20: semanas | G20: Confirmado | H20: 5 sprints quincenales (14 sep – 20 nov 2026)
B21: Equipo | C21: Horas totales de ingeniería (Fases 1 a 9 y 11) | E21: =E18*E19*E20 -> 600 | F21: horas | G21: Calculado | H21: 3 personas × 20 h/sem × 10 sem = 600 horas de desarrollo
B22: Equipo | C22: Tarifa profesional por hora del equipo | E22: 35000 | F22: COP/h | G22: Confirmado | H22: Tarifa de mercado desarrollador junior Colombia ($2.8M-$3.0M base)
B23: Equipo | C23: Horas por Story Point acordadas | E23: 4 | F23: h/SP | G23: Confirmado | H23: 1 Story Point equivale a media jornada de trabajo (4 horas)
B24: Equipo | C24: Capacidad máxima planificada por sprint | E24: 35 | F24: SP | G24: Confirmado | H24: Tope máximo sostenible por sprint sin sobrecarga
B25: Financiero | C25: Tasa Representativa del Mercado (TRM) | E25: 4150 | F25: COP/USD | G25: Confirmado | H25: Tasa promedio proyectada para liquidación de servicios nube
B26: Financiero | C26: Ajuste anual proyectado servicios nube | E26: 0.05 | F26: % anual | G26: Estimado | H26: Inflación tecnológica anual estimada para proyecciones plurianuales
B27: DoD | C27: Código integrado a main por PR (55%) | E27: 0.55 | F27: % horas | G27: Estimado | H27: Escritura de código en Spring Boot, React y flujos n8n
B28: DoD | C28: Pruebas unitarias e integración (20%) | E28: 0.2 | F28: % horas | G28: Estimado | H28: Pruebas JUnit, Mockito, RedisLock y verificación de concurrencia
B29: DoD | C29: Correcciones tras revisión de par y PO (10%) | E29: 0.1 | F29: % horas | G29: Estimado | H29: Ajustes de code review y retroalimentación de criterios de aceptación
B30: DoD | C30: Documentación técnica y OpenAPI (10%) | E30: 0.1 | F30: % horas | G30: Estimado | H30: Swagger/OpenAPI, arquitectura hexagonal y registro de decisiones ADR
B31: DoD | C31: Despliegue en pruebas local/staging (5%) | E31: 0.05 | F31: % horas | G31: Estimado | H31: Contenedores Docker y scripts de verificación para revisión PO
B32: DoD | C32: Costo por Story Point con DoD completa | E32: =E22*E23*(E27+E28+E29+E30+E31) -> 140000 | F32: COP/SP | G32: Calculado | H32: Costo estándar: 4 horas × $35.000/h = $140.000 COP por punto
B33: Negocio | C33: Reservas mensuales promedio hotel | E33: 40 | F33: reservas/mes | G33: Estimado | H33: Capacidad: 9 habitaciones (promedio 35 en baja, 60 en alta)
B34: Negocio | C34: Comisión promedio OTA evitada | E34: 32400 | F34: COP/reserva | G34: Estimado | H34: Comisión Booking/Airbnb del 18% sobre noche base de $180.000 COP
B35: Negocio | C35: Tarifa promedio por noche habitación | E35: 180000 | F35: COP/noche | G35: Estimado | H35: Tarifa promedio ponderada de habitaciones estándar y suites
B37: D.1 RESULTADOS CLAVE DEL ANÁLISIS PRESUPUESTAL
B38: # | C38: Indicador Presupuestal Clave | E38: Valor en COP | F38: Valor en USD | G38: % del Total | H38: Alcance, Componentes y Criterio de Decisión
B39: 1 | C39: Costo de implementación (CAPEX) | E39: =Matriz_Costos!I36 -> 24685000 | F39: =E39/$E$25 -> 5948.1928 | G39: =E39/E41 -> 0.87650152 | H39: Construcción completa de 150 SP ($21.0M) + Puesta en marcha en Sevilla ($1.53M) + Reserva contingencias ($2.15M)
B40: 2 | C40: Costo mensual de operación (OPEX) | E40: =Matriz_Costos!I54 -> 289841.67 | F40: =E40/$E$25 -> 69.841365 | G40: =(E40*12)/E41 -> 0.12349848 | H40: Infraestructura nube ($54.642/mes) + APIs y línea ($55.200/mes) + Soporte preventivo/correctivo ($180.000/mes)
B41: 3 | C41: Costo estimado del primer año (TCO) | E41: =E39+(E40*12) -> 28163100 | F41: =E41/$E$25 -> 6786.2892 | G41: 1 | H41: Costo total de propiedad Año 1: Implementación CAPEX + 12 meses de operación y soporte en producción
B42: 4 | C42: Costos pendientes de validar | E42: =Matriz_Costos!I55 -> 3888400 | F42: =E42/$E$25 -> 936.96386 | G42: =E42/E41 -> 0.13806719 | H42: Rubros basados en supuestos o pendientes de confirmación final con el cliente (no se duplican en el total)
B44: D.2 PRINCIPALES COMPONENTES DE COSTO Y SU JUSTIFICACIÓN TÉCNICA
B45: Componente de Costo | D45: Tipo | E45: Implementación (CAPEX) | F45: Operación 12m (OPEX) | G45: Costo Total Año 1 | H45: % del Total | I45: Justificación Técnica y Causa del Valor
...

Sheet Matriz_Costos
B2: MATRIZ DETALLADA DE COSTOS DEL PROYECTO — CAPEX Y OPEX
B3: Cálculo fundamentado partida por partida · Costo Total = Cantidad × Costo Unitario · Fórmulas dinámicas vinculadas
B5: B.1 CONSTRUCCIÓN DE LA SOLUCIÓN (5 SPRINTS DE DESARROLLO — CAPEX)
B6: # | C6: Componente | D6: Recurso / Actividad / Servicio | E6: Tipo | F6: Cantidad | G6: Unidad | H6: Costo Unitario (COP) | I6: Costo Total (COP) | J6: CAPEX/OPEX | K6: EDT | L6: Validación
B7: 01 | C7: Desarrollo | D7: Horas de programación y codificación (Spring Boot 3.3, React, n8n) | E7: Único | F7: =Historias_Backlog!M48 -> 330 | G7: horas | H7: =Resumen_Ejecutivo!$E$22 -> 35000 | I7: =F7*H7 -> 11550000 | J7: CAPEX | K7: Historias | L7: Confirmado
B8: 02 | C8: Calidad / QA | D8: Horas de pruebas unitarias, integración y concurrencia (DoD 20%) | E8: Único | F8: =Historias_Backlog!N48 -> 120 | G8: horas | H8: =Resumen_Ejecutivo!$E$22 -> 35000 | I8: =F8*H8 -> 4200000 | J8: CAPEX | K8: Historias | L8: Confirmado
B9: 03 | C9: Revisión | D9: Horas de correcciones tras revisión de par y verificación PO (DoD 10%) | E9: Único | F9: =Historias_Backlog!O48 -> 60 | G9: horas | H9: =Resumen_Ejecutivo!$E$22 -> 35000 | I9: =F9*H9 -> 2100000 | J9: CAPEX | K9: Historias | L9: Confirmado
B10: 04 | C10: Documentación | D10: Horas de documentación técnica, Swagger/OpenAPI y ADR (DoD 10%) | E10: Único | F10: =Historias_Backlog!P48 -> 60 | G10: horas | H10: =Resumen_Ejecutivo!$E$22 -> 35000 | I10: =F10*H10 -> 2100000 | J10: CAPEX | K10: Historias | L10: Confirmado
B11: 05 | C11: Despliegue Test | D11: Horas de despliegue en ambiente local y contenedores de prueba (DoD 5%) | E11: Único | F11: =Historias_Backlog!Q48 -> 30 | G11: horas | H11: =Resumen_Ejecutivo!$E$22 -> 35000 | I11: =F11*H11 -> 1050000 | J11: CAPEX | K11: Historias | L11: Confirmado
B12: 06 | C12: Entorno Dev | D12: Herramientas de desarrollo, IDEs y computadores propios del equipo | E12: Único | F12: 1 | G12: entorno | H12: 0 | I12: =F12*H12 -> 0 | J12: CAPEX | K12: 1.0 | L12: Confirmado
B13: 07 | C13: Pruebas WhatsApp | D13: Consumo de Meta WhatsApp Cloud API durante pruebas del semestre | E13: Según uso | F13: 1000 | G13: mensajes | H13: 0 | I13: =F13*H13 -> 0 | J13: CAPEX | K13: 3.0 | L13: Confirmado
B14: 08 | C14: Pruebas IA | D14: Consultas de prueba al modelo Google Gemini Flash Lite en desarrollo | E14: Según uso | F14: 500 | G14: consultas | H14: 0 | I14: =F14*H14 -> 0 | J14: CAPEX | K14: 3.0 | L14: Confirmado
B15: 09 | C15: Pasarela Pruebas | D15: Entorno Sandbox MercadoPago para pruebas de checkout y webhooks | E15: Único | F15: 1 | G15: sandbox | H15: 0 | I15: =F15*H15 -> 0 | J15: CAPEX | K15: 5.0 | L15: Confirmado
B16: SUBTOTAL B.1 | C16: Subtotal Construcción de la Solución (Ingeniería y Desarrollo de 150 SP) | I16: =SUM(I7:I15) -> 21000000
B18: B.2 PUESTA EN OPERACIÓN, PARAMETRIZACIÓN Y CAPACITACIÓN EN SEVILLA (FASE 10 — CAPEX)
B19: # | C19: Componente | D19: Recurso / Actividad / Servicio | E19: Tipo | F19: Cantidad | G19: Unidad | H19: Costo Unitario (COP) | I19: Costo Total (COP) | J19: CAPEX/OPEX | K19: EDT | L19: Validación
B20: 10 | C20: Despliegue | D20: Configuración de servidor VPS de producción, contenedores Docker y Cloudflare Tunnel | E20: Único | F20: 10 | G20: horas | H20: =Resumen_Ejecutivo!$E$22 -> 35000 | I20: =F20*H20 -> 350000 | J20: CAPEX | K20: 10.0 | L20: Estimado
B21: 11 | C21: Integraciones | D21: Gestión y verificación de cuenta comercial en Meta Business Manager para número oficial | E21: Único | F21: 8 | G21: horas | H21: =Resumen_Ejecutivo!$E$22 -> 35000 | I21: =F21*H21 -> 280000 | J21: CAPEX | K21: 10.0 | L21: Estimado
B22: 12 | C22: Parametrización | D22: Carga inicial de habitaciones, fotos, reglas de cobro (RN-01), catálogo e inventario inicial | E22: Único | F22: 10 | G22: horas | H22: =Resumen_Ejecutivo!$E$22 -> 35000 | I22: =F22*H22 -> 350000 | J22: CAPEX | K22: 10.0 | L22: Estimado
B23: 13 | C23: Capacitación | D23: Capacitación presencial al administrador y recepcionista en el hotel en Sevilla | E23: Único | F23: 10 | G23: horas | H23: =Resumen_Ejecutivo!$E$22 -> 35000 | I23: =F23*H23 -> 350000 | J23: CAPEX | K23: 10.0 | L23: Estimado
B24: 14 | C24: Viáticos | D24: Transporte intermunicipal Cali – Sevilla – Cali y alimentación para jornada presencial | E24: Único | F24: 1 | G24: global | H24: 200000 | I24: =F24*H24 -> 200000 | J24: CAPEX | K24: 10.0 | L24: Confirmado
B25: SUBTOTAL B.2 | C25: Subtotal Puesta en Operación, Despliegue y Capacitación en Sevilla | I25: =SUM(I20:I24) -> 1530000
B27: B.3 RESERVA DE CONTINGENCIA CALCULADA RIESGO POR RIESGO (VALOR MONETARIO ESPERADO — CAPEX)
B28: Código | C28: Riesgo Técnico / Operativo | D28: Justificación y Causa Potencial | E28: Tipo | F28: Impacto Si Ocurre | G28: Unidad | H28: Probabilidad | I28: Reserva Asignada (COP) | J28: CAPEX/OPEX | K28: EDT | L28: Estrategia de Mitigación
B29: R-01 | C29: Subida de la tasa de cambio TRM | D29: Fluctuación del dólar por encima de $4.500 COP afectando cobro de VPS y APIs | E29: Riesgo | F29: 300000 | G29: COP | H29: 0.4 | I29: =ROUND(F29*H29,0) -> 120000 | J29: CAPEX | K29: 1.0 | L29: Colchón de cobertura cambiaria anual
B30: R-02 | C30: Demoras en verificación Meta | D30: Trámite extendido de validación comercial de Meta Business Manager para el bot | E30: Riesgo | F30: =20*Resumen_Ejecutivo!$E$22 -> 700000 | G30: COP | H30: 0.6 | I30: =ROUND(F30*H30,0) -> 420000 | J30: CAPEX | K30: 10.0 | L30: Iniciar trámite temprano con documentos del hotel
B31: R-03 | C31: Mayor tráfico de mensajes e IA | D31: Picos de consultas en temporadas turísticas de Sevilla excediendo la bolsa base | E31: Riesgo | F31: 250000 | G31: COP | H31: 0.3 | I31: =ROUND(F31*H31,0) -> 75000 | J31: CAPEX | K31: 3.0 | L31: Optimización de prompts en Gemini y rate limiting
B32: R-04 | C32: Cambio en reglas con stakeholder | D32: Ajustes tardíos en fórmula de sueldo de recepción (HU-07) o fidelización (HU-12) | E32: Riesgo | F32: =40*Resumen_Ejecutivo!$E$22 -> 1400000 | G32: COP | H32: 0.7 | I32: =ROUND(F32*H32,0) -> 980000 | J32: CAPEX | K32: 5.0 | L32: Parámetros configurables en BD en vez de código fijo
B33: R-05 | C33: Complejidad concurrencia Redis | D33: Casos límite en bloqueos temporales concurrentes de habitaciones (RN-02) | E33: Riesgo | F33: =15*Resumen_Ejecutivo!$E$22 -> 525000 | G33: COP | H33: 0.4 | I33: =ROUND(F33*H33,0) -> 210000 | J33: CAPEX | K33: 9.0 | L33: Suite de pruebas automatizadas y scripts Lua atómicos
B34: R-06 | C34: Ajustes de usabilidad en bot/web | D34: Cambios solicitados por el personal del hotel tras la capacitación en recepción | E34: Riesgo | F34: =20*Resumen_Ejecutivo!$E$22 -> 700000 | G34: COP | H34: 0.5 | I34: =ROUND(F34*H34,0) -> 350000 | J34: CAPEX | K34: 10.0 | L34: Prototipado interactivo temprano y validación PO
B35: SUBTOTAL B.3 | C35: Total Reserva de Contingencia Asignada por Riesgos (9,56% de implementación directa) | I35: =SUM(I29:I34) -> 2155000
B36: TOTAL CAPEX | C36: TOTAL COSTO DE IMPLEMENTACIÓN (Construcción B.1 + Puesta en Operación B.2 + Contingencia B.3) | I36: =I16+I25+I35 -> 24685000
B38: C. COSTOS RECURRENTES DE OPERACIÓN Y MANTENIMIENTO EN PRODUCCIÓN (12 MESES — OPEX)
B39: # | C39: Componente | D39: Recurso / Actividad / Servicio | E39: Tipo | F39: Cantidad | G39: Unidad | H39: Costo Unitario (COP) | I39: Costo Total (COP) | J39: CAPEX/OPEX | K39: EDT | L39: Validación
B40: 15 | C40: Infraestructura | D40: Servidor Cloud VPS Linux (4 GB RAM, 2 vCPU, 80 GB SSD para Spring Boot/Redis/n8n/Postgres) | E40: Recurrente | F40: 12 | G40: meses | H40: =ROUND(12*Resumen_Ejecutivo!$E$25,0) -> 49800 | I40: =F40*H40 -> 597600 | J40: OPEX | K40: 10.0 | L40: Confirmado
B41: 16 | C41: Infraestructura | D41: Dominio web oficial (ej. torresatoripms.com) y DNS gestionado | E41: Recurrente | F41: 1 | G41: año | H41: =ROUND(14*Resumen_Ejecutivo!$E$25,0) -> 58100 | I41: =F41*H41 -> 58100 | J41: OPEX | K41: 10.0 | L41: Confirmado
B42: 17 | C42: Infraestructura | D42: Alojamiento web frontend React (Cloudflare Pages / Vercel) | E42: Recurrente | F42: 12 | G42: meses | H42: 0 | I42: =F42*H42 -> 0 | J42: OPEX | K42: 10.0 | L42: Confirmado
B43: 18 | C43: Infraestructura | D43: Almacenamiento de facturas, adjuntos y backups (Cloudflare R2, 10 GB gratis) | E43: Recurrente | F43: 12 | G43: meses | H43: 0 | I43: =F43*H43 -> 0 | J43: OPEX | K43: 10.0 | L43: Confirmado
B44: SUBTOTAL C.1 | C44: Subtotal Infraestructura en la Nube y Dominio (Anual: $655.700 COP | Mensual equiv: $54.642 COP) | I44: =SUM(I40:I43) -> 655700
B45: 19 | C45: Integraciones | D45: Meta WhatsApp Business Cloud API (bolsa de mensajes de confirmación y marketing) | E45: Según uso | F45: 12 | G45: meses | H45: =ROUND(6*Resumen_Ejecutivo!$E$25,0) -> 24900 | I45: =F45*H45 -> 298800 | J45: OPEX | K45: 3.0 | L45: Estimado
...

Sheet Historias_Backlog
B2: CATÁLOGO DE HISTORIAS DE USUARIO, TAREAS TÉCNICAS Y VALOR GANADO (EVM)
B3: Torre Satori PMS · Backlog del MVP (150 Story Points en 5 Sprints) · Definición de Hecho (DoD) y Seguimiento de Valor Ganado
B5: CRITERIO DE AVANCE SEGÚN ESTADO EN EL TABLERO SCRUM
B6: Estado del Tablero | D6: % Avance | E6: Descripción del Criterio de Control
B7: Done | D7: 1 | E7: Criterio de aceptación validado por el Product Owner y DoD cumplida al 100%
B8: QA / Testing | D8: 0.9 | E8: Funcionalidad construida; en pruebas de concurrencia e integración
B9: In Review | D9: 0.8 | E9: Pull request en revisión de pares de código y arquitectura
B10: In Progress | D10: 0.5 | E10: Desarrollo activo de la funcionalidad en el sprint en curso
B11: Blocked | D11: 0.25 | E11: Trabajo iniciado pero bloqueado por dependencia externa o regla pendiente
B12: Ready | D12: 0.1 | E12: Historia refinada con criterios de aceptación lista para iniciar
B13: Backlog | D13: 0 | E13: Historia priorizada en el backlog pendiente de asignación a sprint
B15: ID | C15: Requerimiento / Historia de Usuario / Tarea Técnica | D15: Épica / Módulo | E15: EDT | F15: MoSCoW | G15: MVP | H15: Sprint | I15: Estado | J15: SP | K15: ¿En Presup.? | L15: Horas | M15: Código (55%) | N15: Pruebas (20%) | O15: Correc. (10%) | P15: Docum. (10%) | Q15: Despl. (5%) | R15: Costo Total (COP) | S15: % Avance | T15: SP Ganados | U15: Costo Ejecutado (EV)
B16: HUT-01 | C16: Configurar repositorios, monorepo, Docker Compose y DoD | D16: E0 · Plataforma | E16: 2.0 | F16: Must have | G16: MVP | H16: Sprint 1 | I16: Done | J16: 2 | K16: Sí | L16: =IF(K16="Sí",J16*Resumen_Ejecutivo!$E$23,0) -> 8 | M16: =L16*Resumen_Ejecutivo!$E$27 -> 4.4 | N16: =L16*Resumen_Ejecutivo!$E$28 -> 1.6 | O16: =L16*Resumen_Ejecutivo!$E$29 -> 0.8 | P16: =L16*Resumen_Ejecutivo!$E$30 -> 0.8 | Q16: =L16*Resumen_Ejecutivo!$E$31 -> 0.4 | R16: =L16*Resumen_Ejecutivo!$E$22 -> 280000 | S16: =IFERROR(INDEX($D$7:$D$13,MATCH(I16,$B$7:$B$13,0)),0) -> 1 | T16: =J16*S16 -> 2 | U16: =R16*S16 -> 280000
B17: HUT-02 | C17: Diseñar arquitectura hexagonal Spring Boot y modelo PostgreSQL/Redis | D17: E0 · Plataforma | E17: 2.0 | F17: Must have | G17: MVP | H17: Sprint 1 | I17: Done | J17: 5 | K17: Sí | L17: =IF(K17="Sí",J17*Resumen_Ejecutivo!$E$23,0) -> 20 | M17: =L17*Resumen_Ejecutivo!$E$27 -> 11 | N17: =L17*Resumen_Ejecutivo!$E$28 -> 4 | O17: =L17*Resumen_Ejecutivo!$E$29 -> 2 | P17: =L17*Resumen_Ejecutivo!$E$30 -> 2 | Q17: =L17*Resumen_Ejecutivo!$E$31 -> 1 | R17: =L17*Resumen_Ejecutivo!$E$22 -> 700000 | S17: =IFERROR(INDEX($D$7:$D$13,MATCH(I17,$B$7:$B$13,0)),0) -> 1 | T17: =J17*S17 -> 5 | U17: =R17*S17 -> 700000
B18: HUT-03 | C18: Implementar autenticación JWT, roles y control de acceso RBAC | D18: E6 · Seguridad | E18: 8.0 | F18: Must have | G18: MVP | H18: Sprint 1 | I18: Done | J18: 5 | K18: Sí | L18: =IF(K18="Sí",J18*Resumen_Ejecutivo!$E$23,0) -> 20 | M18: =L18*Resumen_Ejecutivo!$E$27 -> 11 | N18: =L18*Resumen_Ejecutivo!$E$28 -> 4 | O18: =L18*Resumen_Ejecutivo!$E$29 -> 2 | P18: =L18*Resumen_Ejecutivo!$E$30 -> 2 | Q18: =L18*Resumen_Ejecutivo!$E$31 -> 1 | R18: =L18*Resumen_Ejecutivo!$E$22 -> 700000 | S18: =IFERROR(INDEX($D$7:$D$13,MATCH(I18,$B$7:$B$13,0)),0) -> 1 | T18: =J18*S18 -> 5 | U18: =R18*S18 -> 700000
B19: HUT-04 | C19: Implementar scripts Lua y RedisLockService para bloqueo 15 min anti-overbooking (RN-02) | D19: E0 · Plataforma | E19: 2.0 | F19: Must have | G19: MVP | H19: Sprint 1 | I19: Done | J19: 5 | K19: Sí | L19: =IF(K19="Sí",J19*Resumen_Ejecutivo!$E$23,0) -> 20 | M19: =L19*Resumen_Ejecutivo!$E$27 -> 11 | N19: =L19*Resumen_Ejecutivo!$E$28 -> 4 | O19: =L19*Resumen_Ejecutivo!$E$29 -> 2 | P19: =L19*Resumen_Ejecutivo!$E$30 -> 2 | Q19: =L19*Resumen_Ejecutivo!$E$31 -> 1 | R19: =L19*Resumen_Ejecutivo!$E$22 -> 700000 | S19: =IFERROR(INDEX($D$7:$D$13,MATCH(I19,$B$7:$B$13,0)),0) -> 1 | T19: =J19*S19 -> 5 | U19: =R19*S19 -> 700000
B20: HUT-05 | C20: Implementar restricción de exclusión transaccional PostgreSQL EXCLUDE USING gist (RN-02) | D20: E0 · Plataforma | E20: 2.0 | F20: Must have | G20: MVP | H20: Sprint 1 | I20: Done | J20: 5 | K20: Sí | L20: =IF(K20="Sí",J20*Resumen_Ejecutivo!$E$23,0) -> 20 | M20: =L20*Resumen_Ejecutivo!$E$27 -> 11 | N20: =L20*Resumen_Ejecutivo!$E$28 -> 4 | O20: =L20*Resumen_Ejecutivo!$E$29 -> 2 | P20: =L20*Resumen_Ejecutivo!$E$30 -> 2 | Q20: =L20*Resumen_Ejecutivo!$E$31 -> 1 | R20: =L20*Resumen_Ejecutivo!$E$22 -> 700000 | S20: =IFERROR(INDEX($D$7:$D$13,MATCH(I20,$B$7:$B$13,0)),0) -> 1 | T20: =J20*S20 -> 5 | U20: =R20*S20 -> 700000
B21: HUT-06 | C21: Crear migraciones Flyway V1 a V5 (tablas, catálogos e índices) | D21: E0 · Plataforma | E21: 2.0 | F21: Must have | G21: MVP | H21: Sprint 1 | I21: Done | J21: 3 | K21: Sí | L21: =IF(K21="Sí",J21*Resumen_Ejecutivo!$E$23,0) -> 12 | M21: =L21*Resumen_Ejecutivo!$E$27 -> 6.6 | N21: =L21*Resumen_Ejecutivo!$E$28 -> 2.4 | O21: =L21*Resumen_Ejecutivo!$E$29 -> 1.2 | P21: =L21*Resumen_Ejecutivo!$E$30 -> 1.2 | Q21: =L21*Resumen_Ejecutivo!$E$31 -> 0.6 | R21: =L21*Resumen_Ejecutivo!$E$22 -> 420000 | S21: =IFERROR(INDEX($D$7:$D$13,MATCH(I21,$B$7:$B$13,0)),0) -> 1 | T21: =J21*S21 -> 3 | U21: =R21*S21 -> 420000
B22: HU-03a | C22: Construir modelo de habitaciones, estados (D/O/M/B) y tarifas base por tipo (RN-01) | D22: E2 · Habitaciones | E22: 4.0 | F22: Must have | G22: MVP | H22: Sprint 1 | I22: Done | J22: 5 | K22: Sí | L22: =IF(K22="Sí",J22*Resumen_Ejecutivo!$E$23,0) -> 20 | M22: =L22*Resumen_Ejecutivo!$E$27 -> 11 | N22: =L22*Resumen_Ejecutivo!$E$28 -> 4 | O22: =L22*Resumen_Ejecutivo!$E$29 -> 2 | P22: =L22*Resumen_Ejecutivo!$E$30 -> 2 | Q22: =L22*Resumen_Ejecutivo!$E$31 -> 1 | R22: =L22*Resumen_Ejecutivo!$E$22 -> 700000 | S22: =IFERROR(INDEX($D$7:$D$13,MATCH(I22,$B$7:$B$13,0)),0) -> 1 | T22: =J22*S22 -> 5 | U22: =R22*S22 -> 700000
B23: HUT-07 | C23: Orquestar n8n y configurar webhook de WhatsApp con reintentos automáticos | D23: E1 · Chatbot | E23: 3.0 | F23: Must have | G23: MVP | H23: Sprint 2 | I23: Done | J23: 5 | K23: Sí | L23: =IF(K23="Sí",J23*Resumen_Ejecutivo!$E$23,0) -> 20 | M23: =L23*Resumen_Ejecutivo!$E$27 -> 11 | N23: =L23*Resumen_Ejecutivo!$E$28 -> 4 | O23: =L23*Resumen_Ejecutivo!$E$29 -> 2 | P23: =L23*Resumen_Ejecutivo!$E$30 -> 2 | Q23: =L23*Resumen_Ejecutivo!$E$31 -> 1 | R23: =L23*Resumen_Ejecutivo!$E$22 -> 700000 | S23: =IFERROR(INDEX($D$7:$D$13,MATCH(I23,$B$7:$B$13,0)),0) -> 1 | T23: =J23*S23 -> 5 | U23: =R23*S23 -> 700000
B24: CU-01 | C24: Construir flujo conversacional de reserva guiada por WhatsApp con cálculo de abono 50%/100% | D24: E1 · Chatbot | E24: 3.0 | F24: Must have | G24: MVP | H24: Sprint 2 | I24: Done | J24: 8 | K24: Sí | L24: =IF(K24="Sí",J24*Resumen_Ejecutivo!$E$23,0) -> 32 | M24: =L24*Resumen_Ejecutivo!$E$27 -> 17.6 | N24: =L24*Resumen_Ejecutivo!$E$28 -> 6.4 | O24: =L24*Resumen_Ejecutivo!$E$29 -> 3.2 | P24: =L24*Resumen_Ejecutivo!$E$30 -> 3.2 | Q24: =L24*Resumen_Ejecutivo!$E$31 -> 1.6 | R24: =L24*Resumen_Ejecutivo!$E$22 -> 1120000 | S24: =IFERROR(INDEX($D$7:$D$13,MATCH(I24,$B$7:$B$13,0)),0) -> 1 | T24: =J24*S24 -> 8 | U24: =R24*S24 -> 1120000
B25: CU-02a | C25: Construir consulta de reserva por código o documento con detalle de estado y fechas | D25: E1 · Chatbot | E25: 3.0 | F25: Must have | G25: MVP | H25: Sprint 2 | I25: Done | J25: 5 | K25: Sí | L25: =IF(K25="Sí",J25*Resumen_Ejecutivo!$E$23,0) -> 20 | M25: =L25*Resumen_Ejecutivo!$E$27 -> 11 | N25: =L25*Resumen_Ejecutivo!$E$28 -> 4 | O25: =L25*Resumen_Ejecutivo!$E$29 -> 2 | P25: =L25*Resumen_Ejecutivo!$E$30 -> 2 | Q25: =L25*Resumen_Ejecutivo!$E$31 -> 1 | R25: =L25*Resumen_Ejecutivo!$E$22 -> 700000 | S25: =IFERROR(INDEX($D$7:$D$13,MATCH(I25,$B$7:$B$13,0)),0) -> 1 | T25: =J25*S25 -> 5 | U25: =R25*S25 -> 700000
B26: CU-02b | C26: Construir liquidación y pago del saldo restante en recepción o WhatsApp | D26: E1 · Chatbot | E26: 3.0 | F26: Must have | G26: MVP | H26: Sprint 2 | I26: Done | J26: 4 | K26: Sí | L26: =IF(K26="Sí",J26*Resumen_Ejecutivo!$E$23,0) -> 16 | M26: =L26*Resumen_Ejecutivo!$E$27 -> 8.8 | N26: =L26*Resumen_Ejecutivo!$E$28 -> 3.2 | O26: =L26*Resumen_Ejecutivo!$E$29 -> 1.6 | P26: =L26*Resumen_Ejecutivo!$E$30 -> 1.6 | Q26: =L26*Resumen_Ejecutivo!$E$31 -> 0.8 | R26: =L26*Resumen_Ejecutivo!$E$22 -> 560000 | S26: =IFERROR(INDEX($D$7:$D$13,MATCH(I26,$B$7:$B$13,0)),0) -> 1 | T26: =J26*S26 -> 4 | U26: =R26*S26 -> 560000
B27: CU-02c | C27: Construir cancelación de reservas grupales/individuales y política de reembolso (RN-03) | D27: E1 · Chatbot | E27: 3.0 | F27: Must have | G27: MVP | H27: Sprint 2 | I27: Done | J27: 5 | K27: Sí | L27: =IF(K27="Sí",J27*Resumen_Ejecutivo!$E$23,0) -> 20 | M27: =L27*Resumen_Ejecutivo!$E$27 -> 11 | N27: =L27*Resumen_Ejecutivo!$E$28 -> 4 | O27: =L27*Resumen_Ejecutivo!$E$29 -> 2 | P27: =L27*Resumen_Ejecutivo!$E$30 -> 2 | Q27: =L27*Resumen_Ejecutivo!$E$31 -> 1 | R27: =L27*Resumen_Ejecutivo!$E$22 -> 700000 | S27: =IFERROR(INDEX($D$7:$D$13,MATCH(I27,$B$7:$B$13,0)),0) -> 1 | T27: =J27*S27 -> 5 | U27: =R27*S27 -> 700000
... B47: HUT-09 | C47: Configurar despliegue en VPS Linux de producción con Docker y Cloudflare | D47: E0 · Plataforma | E47: 10.0 | F47: Must have | G47: MVP | H47: Sprint 5 | I47: Ready | J47: 5 | K47: Sí | L47: =IF(K47="Sí",J47*Resumen_Ejecutivo!$E$23,0) -> 20 | M47: =L47*Resumen_Ejecutivo!$E$27 -> 11 | N47: =L47*Resumen_Ejecutivo!$E$28 -> 4 | O47: =L47*Resumen_Ejecutivo!$E$29 -> 2 | P47: =L47*Resumen_Ejecutivo!$E$30 -> 2 | Q47: =L47*Resumen_Ejecutivo!$E$31 -> 1 | R47: =L47*Resumen_Ejecutivo!$E$22 -> 700000 | S47: =IFERROR(INDEX($D$7:$D$13,MATCH(I47,$B$7:$B$13,0)),0) -> 0.1 | T47: =J47*S47 -> 0.5 | U47: =R47*S47 -> 70000
B48: TOTAL | C48: Total Consolidado del Backlog SatoriPMS (150 Story Points de Ingeniería) | J48: =SUM(J16:J47) -> 150 | L48: =SUM(L16:L47) -> 600 | M48: =SUM(M16:M47) -> 330 | N48: =SUM(N16:N47) -> 120 | O48: =SUM(O16:O47) -> 60 | P48: =SUM(P16:P47) -> 60 | Q48: =SUM(Q16:Q47) -> 30 | R48: =SUM(R16:R47) -> 21000000 | S48: =IF(J48>0,T48/J48,0) -> 0.61333333 | T48: =SUM(T16:T47) -> 92 | U48: =SUM(U16:U47) -> 12880000

Sheet Escenarios_Decisiones
B2: TORRE SATORI PMS — ANÁLISIS DE ESCENARIOS FINANCIEROS Y SENSIBILIDAD
B3: Evaluación comparativa de alternativas de alcance (Base vs. Optimizado vs. Expandido), Proyección TCO a 3 Años y Sensibilidad
B5: 1. COMPARATIVA DE ESCENARIOS DE ALCANCE, COSTOS Y RETORNO DE INVERSIÓN
B6: Métrica / Parámetro Presupuestal | C6: Unidad | D6: Escenario Optimizado (Lean / MVP Esencial) | E6: Escenario Base (MVP Torre Satori) | F6: Escenario Expandido (Multi-propiedad / IoT) | G6: Diferencia (Opt vs Base) | H6: Diferencia (Exp vs Base)
B7: Alcance en Story Points (Backlog) | C7: SP | D7: 143 | E7: 150 | F7: 195 | G7: =D7-E7 -> -7 | H7: =F7-E7 -> 45
B8: Horas totales estimadas de ingeniería | C8: Horas | D8: =D7*Resumen_Ejecutivo!$E$23 -> 572 | E8: =E7*Resumen_Ejecutivo!$E$23 -> 600 | F8: =F7*Resumen_Ejecutivo!$E$23 -> 780 | G8: =D8-E8 -> -28 | H8: =F8-E8 -> 180
B9: Costo total de implementación (CAPEX) | C9: COP | D9: =E9-1400000 -> 23285000 | E9: =Matriz_Costos!I36 -> 24685000 | F9: =E9+7800000 -> 32485000 | G9: =D9-E9 -> -1400000 | H9: =F9-E9 -> 7800000
B10: Costo mensual de operación (OPEX) | C10: COP/mes | D10: =E10-60000 -> 229841.67 | E10: =Matriz_Costos!I54 -> 289841.67 | F10: =E10+120000 -> 409841.67 | G10: =D10-E10 -> -60000 | H10: =F10-E10 -> 120000
B11: Costo anual de operación (OPEX Anual) | C11: COP/año | D11: =D10*12 -> 2758100 | E11: =E10*12 -> 3478100 | F11: =F10*12 -> 4918100 | G11: =D11-E11 -> -720000 | H11: =F11-E11 -> 1440000
B12: Costo Total de Propiedad Año 1 (TCO) | C12: COP | D12: =D9+D11 -> 26043100 | E12: =E9+E11 -> 28163100 | F12: =F9+F11 -> 37403100 | G12: =D12-E12 -> -2120000 | H12: =F12-E12 -> 9240000
B13: Variación porcentual TCO vs. Escenario Base | C13: % | D13: =(D12-E12)/E12 -> -0.075275804 | E13: 0 | F13: =(F12-E12)/E12 -> 0.32808888 | G13: =(D12-E12)/E12 -> -0.075275804 | H13: =(F12-E12)/E12 -> 0.32808888
B14: Período de recuperación estimado (Payback) | C14: Meses | D14: =D9/((Resumen_Ejecutivo!$E$69+Resumen_Ejecutivo!$E$70)/12) -> 12.938567 | E14: =E9/((Resumen_Ejecutivo!$E$69+Resumen_Ejecutivo!$E$70)/12) -> 13.716492 | F14: =F9/((Resumen_Ejecutivo!$E$69+Resumen_Ejecutivo!$E$70*1.15)/12) -> 17.028731 | G14: =D14-E14 -> -0.77792544 | H14: =F14-E14 -> 3.3122382
B15: Evaluación de riesgo y cobertura de negocio | C15: Texto | D15: Bajo (Difiere analítica compleja a Fase 2) | E15: Óptimo (Balance costo/beneficio validado) | F15: Medio-Alto (Dependencia de APIs de OTAs e IoT) | G15: Menor inversión | H15: Mayor complejidad
B17: 2. PROYECCIÓN DEL COSTO TOTAL DE PROPIEDAD (TCO) A 3 AÑOS (ESCENARIO BASE)
B18: Componente Presupuestal | C18: Base de Cálculo y Supuesto de Proyección | D18: Unidad | E18: Año 1 (2026-2027) | F18: Año 2 (2027-2028) | G18: Año 3 (2028-2029) | H18: Total 3 Años (TCO)
B19: CAPEX: Inversión Inicial (Desarrollo + Despliegue + Contingencia) | C19: Inversión única en fase de implementación | D19: COP | E19: =Matriz_Costos!I36 -> 24685000 | F19: 0 | G19: 0 | H19: =SUM(E19:G19) -> 24685000
B20: OPEX: Infraestructura Cloud (VPS Hetzner + Dominio + Cloudflare) | C20: Inflación tecnológica proyectada 5% anual | D20: COP/año | E20: =Matriz_Costos!I44 -> 655700 | F20: =E20*(1+Resumen_Ejecutivo!$E$26) -> 688485 | G20: =F20*(1+Resumen_Ejecutivo!$E$26) -> 722909.25 | H20: =SUM(E20:G20) -> 2067094.2
B21: OPEX: APIs y Conectividad (Meta WhatsApp + Gemini Flash + SIM) | C21: Inflación tecnológica proyectada 5% anual | D21: COP/año | E21: =Matriz_Costos!I49 -> 662400 | F21: =E21*(1+Resumen_Ejecutivo!$E$26) -> 695520 | G21: =F21*(1+Resumen_Ejecutivo!$E$26) -> 730296 | H21: =SUM(E21:G21) -> 2088216
B22: Subtotal Servicios Tecnológicos Operativos | C22: Suma de VPS, Dominio, Meta y Gemini IA | D22: COP/año | E22: =E20+E21 -> 1318100 | F22: =F20+F21 -> 1384005 | G22: =G20+G21 -> 1453205.2 | H22: =SUM(E22:G22) -> 4155310.2
B23: OPEX: Soporte Técnico Preventivo y Correctivo (5 h/mes) | C23: Reajuste salarial IPC proyectado 6% anual | D23: COP/año | E23: =Matriz_Costos!I52 -> 2160000 | F23: =E23*(1+0.06) -> 2289600 | G23: =F23*(1+0.06) -> 2426976 | H23: =SUM(E23:G23) -> 6876576
B24: TOTAL OPEX ANUAL (Sostenimiento y Operación) | C24: Infraestructura + APIs + Soporte Técnico | D24: COP/año | E24: =E22+E23 -> 3478100 | F24: =F22+F23 -> 3673605 | G24: =G22+G23 -> 3880181.2 | H24: =SUM(E24:G24) -> 11031886
B25: TOTAL FLUJO DE CAJA ANUAL (CAPEX + OPEX) | C25: Desembolso efectivo consolidado por período | D25: COP/año | E25: =E19+E24 -> 28163100 | F25: =F19+F24 -> 3673605 | G25: =G19+G24 -> 3880181.2 | H25: =SUM(E25:G25) -> 35716886
B26: TCO ACUMULADO PROGRESIVO | C26: Costo Total de Propiedad acumulado al final del año | D26: COP | E26: =E25 -> 28163100 | F26: =E26+F25 -> 31836705 | G26: =F26+G25 -> 35716886 | H26: =G26 -> 35716886
B28: 3. ANÁLISIS DE SENSIBILIDAD OPERATIVA Y PUNTOS DE QUIEBRE
B29: Variable o Factor de Riesgo Sensible | C29: Rango de Variación Evaluado | D29: Unidad | E29: Caso Favorable / Optimista | F29: Caso Base / Presupuestado | G29: Caso Desfavorable / Severo | H29: Impacto y Mitigación Estratégica
B30: Sensibilidad a la TRM (COP / USD) | C30: -10% favorable / +20% devaluación severa | D30: COP/USD | E30: 3735 | F30: =Resumen_Ejecutivo!$E$25 -> 4150 | G30: 4980 | H30: Impacto muy bajo (<$23.000 COP/mes en servidores y APIs)
B31: Costo mensual en dólares de Nube y APIs | C31: 18 USD/mes (VPS Hetzner + Meta + Gemini) | D31: COP/mes | E31: =3735*18 -> 67230 | F31: =Resumen_Ejecutivo!$E$25*18 -> 74700 | G31: =4980*18 -> 89640 | H31: Absorbido plenamente por la contingencia presupuestal
B32: Sensibilidad al Volumen de Reservas Directas | C32: 20 reservas (baja) vs 40 (base) vs 60 (alta) | D32: reservas/mes | E32: 60 | F32: =Resumen_Ejecutivo!$E$33 -> 40 | G32: 20 | H32: A mayor reserva directa, mayor es el retorno y ahorro
B33: Comisiones ahorradas a agencias OTAs al mes | C33: 18% evitado sobre tarifa promedio de $180k | D33: COP/mes | E33: =E32*Resumen_Ejecutivo!$E$34 -> 1944000 | F33: =F32*Resumen_Ejecutivo!$E$34 -> 1296000 | G33: =G32*Resumen_Ejecutivo!$E$34 -> 648000 | H33: Ahorro directo en flujo de caja de Torre Satori
B34: Período de recuperación (Payback) según demanda | C34: Meses para amortizar el CAPEX total ($24.68M) | D34: Meses | E34: =Matriz_Costos!$I$36/((E33*12+Resumen_Ejecutivo!$E$70)/12) -> 9.2661411 | F34: =Matriz_Costos!$I$36/((F33*12+Resumen_Ejecutivo!$E$70)/12) -> 12.244544 | G34: =Matriz_Costos!$I$36/((G33*12+Resumen_Ejecutivo!$E$70)/12) -> 18.044591 | H34: Incluso en escenario de baja demanda se recupera en <21 meses
B35: Sensibilidad a la Tarifa Horaria de Ingeniería | C35: $30.000/h (junior) vs $35.000/h vs $40.000/h (senior) | D35: COP/hora | E35: 30000 | F35: =Resumen_Ejecutivo!$E$22 -> 35000 | G35: 40000 | H35: Acordada y fijada mediante contrato de desarrollo cerrado
B36: Costo de Desarrollo e Ingeniería (B.1 - 600h) | C36: 600 horas efectivas de programación de 3 ingenieros | D36: COP | E36: =E35*600 -> 18000000 | F36: =F35*600 -> 21000000 | G36: =G35*600 -> 24000000 | H36: Controlado mediante sprints cerrados de 120 horas cada uno
B38: 4. DICTAMEN Y RECOMENDACIÓN ESTRATÉGICA PRESUPUESTAL PARA TORRE SATORI
B39: Decisión Recomendada | C39: ADOPTAR EL ESCENARIO BASE (150 SP - $24.685.000 COP CAPEX / $289.842 COP/mes OPEX)
B40: Fundamentación Técnica | C40: El Escenario Base implementa con exactitud los 14 módulos neurálgicos requeridos por el hotel boutique en Sevilla, Valle del Cauca: doble candado contra sobreventa (RedisLockService + PostgreSQL EXCLUDE GIST), motor de reservas 24/7 en WhatsApp, integración de pasarela MercadoPago con abono del 50%/100%, panel administrativo web y módulos contables/inventario.
B41: Eficiencia en Infraestructura | C41: La arquitectura auto-alojada en VPS (Hetzner CX23 de 4GB RAM a $12 USD/mes) combinada con el CDN y almacenamiento gratuito de Cloudflare (Pages y R2) reduce los costos fijos a solo $54.642 COP/mes, evitando licencias comerciales propietarias como Cloudbeds o Mews que cobran más de $330 USD/mes ($1.369.500 COP/mes).
B42: Estrategia ante Restricción | C42: En caso de una restricción de liquidez estricta antes de iniciar el Sprint 4, el hotel puede migrar de forma inmediata al Escenario Optimizado difiriendo 7 Story Points de analítica avanzada ($1.400.000 COP de ahorro) sin afectar en lo absoluto las operaciones de reserva, check-in, cobro y facturación.
B43: Punto de Equilibrio (Break-even) | C43: Con procesar únicamente 3 reservas directas al mes por WhatsApp ($97.200 COP de comisiones de OTAs evitadas), el hotel cubre el 100% de sus costos operativos de servidores, Meta WhatsApp Cloud API y Gemini Flash Lite ($109.842 COP/mes). El proyecto es financieramente blindado y de muy bajo riesgo.

Sheet Supuestos_Validaciones
B2: TORRE SATORI PMS — MATRIZ DE SUPUESTOS, PARÁMETROS Y VALIDACIÓN DE COSTOS
B3: Registro de trazabilidad técnica, fuentes oficiales de cotización, estado de validación y gestión de riesgos económicos (Guion 3)
B5: 1. MATRIZ DE PARÁMETROS TÉCNICOS, ECONÓMICOS Y SUPUESTOS OPERATIVOS
B6: ID Parámetro | C6: Categoría | D6: Nombre del Parámetro / Variable Presupuestal | E6: Valor en Presupuesto | F6: Unidad | G6: Tipo de Fuente | H6: Entidad / Origen Verificable | I6: Estado de Validación | J6: Nivel de Impacto | K6: Justificación Técnica y Acción de Mitigación
B7: PAR-01 | C7: Laboral / Dev | D7: Tarifa horaria profesional del equipo | E7: =Resumen_Ejecutivo!$E$22 -> 35000 | F7: COP/hora | G7: Tarifa acordada | H7: Contrato equipo de ingeniería | I7: Confirmado | J7: Alto | K7: Tarifa fija por entregables de Sprint (30 SP por sprint = $4.200.000 COP)
B8: PAR-02 | C8: Metodología Ágil | D8: Esfuerzo estándar por Story Point | E8: =Resumen_Ejecutivo!$E$23 -> 4 | F8: Horas/SP | G8: Histórico Scrum | H8: Planning Poker del equipo | I8: Confirmado | J8: Alto | K8: DoD completa: 55% código, 20% pruebas, 10% review, 10% docs, 5% staging
B9: PAR-03 | C9: Alcance | D9: Tamaño total del Backlog MVP | E9: =Historias_Backlog!J48 -> 150 | F9: SP | G9: Especificación técnica | H9: 14 módulos Torre Satori | I9: Confirmado | J9: Alto | K9: Backlog cerrado priorizado; control formal de cambios ante solicitudes nuevas
B10: PAR-04 | C10: Macroeconómico | D10: Tasa Representativa del Mercado (TRM) | E10: =Resumen_Ejecutivo!$E$25 -> 4150 | F10: COP/USD | G10: Oficial de mercado | H10: Banco de la República (Oct 2026) | I10: Confirmado | J10: Bajo | K10: Aplica únicamente sobre ~18 USD/mes de nube y APIs; impacto mínimo en flujo
B11: PAR-05 | C11: Infraestructura | D11: Servidor VPS Producción Hetzner CX23 | E11: =Matriz_Costos!F40 -> 12 | F11: USD/mes | G11: Cotización oficial | H11: Hetzner Online GmbH (Alemania) | I11: Confirmado | J11: Bajo | K11: 4 GB RAM, 2 vCPU, NVMe; suficiente para Spring Boot, Redis, Postgres y n8n
B12: PAR-06 | C12: Infraestructura | D12: Registro Dominio .com y DNS Cloudflare | E12: =Matriz_Costos!F41 -> 1 | F12: USD/año | G12: Tarifa pública at-cost | H12: Cloudflare Registrar | I12: Confirmado | J12: Muy Bajo | K12: Dominio propio .com a precio de costo ICANN ($10.46) + renovación con tarjeta corporativa
B13: PAR-07 | C13: Infraestructura | D13: Alojamiento Frontend SPA en Cloudflare Pages | E13: =Matriz_Costos!F42 -> 12 | F13: COP/mes | G13: Plan Gratuito Oficial | H13: Cloudflare Pages | I13: Confirmado | J13: Nulo | K13: Builds y ancho de banda ilimitados con CDN global Anycast; $0 costo recurrente
B14: PAR-08 | C14: Almacenamiento | D14: Almacenamiento Comprobantes Cloudflare R2 | E14: =Matriz_Costos!F43 -> 12 | F14: COP/mes | G14: Plan Gratuito Oficial | H14: Cloudflare R2 Storage | I14: Confirmado | J14: Muy Bajo | K14: 10 GB/mes incluidos con $0 costo de egreso; capacidad para >30.000 comprobantes
B15: PAR-09 | C15: Conectividad / APIs | D15: Meta WhatsApp Cloud API (Conversaciones) | E15: =Matriz_Costos!F45 -> 12 | F15: USD/mes | G15: Tarifario Meta Colombia | H15: Meta for Developers | I15: Estimado | J15: Medio | K15: 1.000 conversaciones de servicio/mes gratuitas; se presupuestan 300 plantillas
B16: PAR-10 | C16: Inteligencia Artificial | D16: Google Gemini Flash Lite LLM (Tokens) | E16: =Matriz_Costos!F46 -> 12 | F16: USD/mes | G16: Tarifario Oficial Google | H16: Google AI Studio Pricing | I16: Estimado | J16: Bajo | K16: $0.25/M input tokens, $1.50/M output tokens; prompts compactos con pre-filtrado n8n
B17: PAR-11 | C17: Telecomunicaciones | D17: Línea Móvil SIM Card para Bot WhatsApp | E17: =Matriz_Costos!F47 -> 12 | F17: COP/mes | G17: Plan Prepago / Postpago | H17: Claro / Tigo Colombia | I17: Pendiente | J17: Muy Bajo | K17: Pendiente de adquisición de tarjeta SIM física para registro en WhatsApp Business
B18: PAR-12 | C18: Pasarela de Pagos | D18: MercadoPago Sandbox y Producción | E18: =Matriz_Costos!F48 -> 12 | F18: COP/mes | G18: Tarifario Oficial Pasarela | H18: MercadoPago Colombia | I18: Confirmado | J18: Operativo | K18: Cero cargo fijo mensual; comisión de 3.29% + IVA deducida directamente del abono
B19: PAR-13 | C19: Despliegue Presencial | D19: Puesta en Marcha en Sevilla, Valle | E19: =Matriz_Costos!I25 -> 1530000 | F19: COP | G19: Cotización de viáticos + dev | H19: Equipo de Desarrollo e Icesi | I19: Confirmado | J19: Medio | K19: 38 horas de ingeniería ($1.330.000) + $200.000 viáticos Cali-Sevilla-Cali (3 días)
B20: PAR-14 | C20: Gestión de Riesgos | D20: Reserva de Contingencia Probabilística VME | E20: =Matriz_Costos!I35 -> 2155000 | F20: COP | G20: Metodología VME Cuantitativa | H20: Matriz de Riesgos R-01..R-06 | I20: Confirmado | J20: Alto | K20: 9.56% de la inversión directa; desembolso condicionado a autorización del PO
B21: PAR-15 | C21: Operación / Soporte | D21: Bolsa de Soporte y Mantenimiento Técnico | E21: =Matriz_Costos!I52 -> 2160000 | F21: COP/año | G21: SLA Preventivo Acordado | H21: Equipo de Ingeniería | I21: Estimado | J21: Medio | K21: 5 horas mensuales a $36.000 COP/h ($180.000 COP/mes) para parches y backups
B22: PAR-16 | C22: Negocio Hotelero | D22: Volumen Promedio de Reservas de Torre Satori | E22: =Resumen_Ejecutivo!$E$33 -> 40 | F22: reservas/mes | G22: Histórico Operativo Hotel | H22: Administración Torre Satori | I22: Confirmado | J22: Alto | K22: 9 habitaciones al 60% ocupación = 162 noches-hab/mes; estancia media 2.5 noches
B23: PAR-17 | C23: Negocio Hotelero | D23: Tarifa Promedio por Noche Habitación | E23: =Resumen_Ejecutivo!$E$35 -> 180000 | F23: COP/noche | G23: Tarifario Oficial 2026 | H23: Administración Torre Satori | I23: Confirmado | J23: Alto | K23: Tarifa promedio ponderada de habitaciones estándar y superiores en Sevilla
B24: PAR-18 | C24: Negocio Hotelero | D24: Comisión Promedio Evitada Agencias OTAs | E24: =Resumen_Ejecutivo!$E$34 -> 32400 | F24: COP/reserva | G24: Comisión Booking / Airbnb | H24: Mercado Hotelero Colombia (18%) | I24: Confirmado | J24: Alto | K24: 18% ahorrado sobre noche base de $180.000 COP al reservar vía WhatsApp directo
B26: 2. CONSOLIDADO DE AUDITORÍA PRESUPUESTAL Y MONTO SUJETO A VALIDACIÓN
B27: Estado de Validación | C27: Criterio Técnico y Documental | D27: Cantidad Parámetros | E27: % del Total | F27: Monto Presupuestal Asociado (COP) | G27: Acción y Responsable para Formalización
B28: Confirmado / Validado | C28: Respaldado por cotización oficial, tarifa contractual o histórico de hotel | D28: =COUNTIF(I7:I24,"Confirmado") -> 14 | E28: =D28/$D$32 -> 0.73684211 | F28: =Matriz_Costos!I36+Matriz_Costos!I44+Matriz_Costos!I48-Matriz_Costos!I55 -> 21452300 | G28: Formalizado; no requiere acciones adicionales de validación
B29: Estimado Técnicamente | C29: Basado en volumetría proyectada y tarifas de consumo (Meta, Gemini, Soporte) | D29: =COUNTIF(I7:I24,"Estimado") -> 3 | E29: =D29/$D$32 -> 0.15789474 | F29: =Matriz_Costos!I45+Matriz_Costos!I46+Matriz_Costos!I52 -> 2558400 | G29: Monitorear consumo real en fase de pruebas con usuarios piloto
B30: Pendiente de Contratación | C30: Requiere compra de SIM prepago física para activación del bot WhatsApp | D30: =COUNTIF(I7:I24,"Pendiente") -> 1 | E30: =D30/$D$32 -> 0.052631579 | F30: =Matriz_Costos!I47 -> 264000 | G30: Adquirir tarjeta SIM corporativa previo al inicio del Sprint 2
B31: Reserva de Contingencia | C31: Fondo probabilístico calculado por riesgos técnicos (VME R-01 a R-06) | D31: 1 | E31: =D31/$D$32 -> 0.052631579 | F31: =Matriz_Costos!I35 -> 2155000 | G31: Desembolso sujeto a aprobación formal expresa del Product Owner
B32: TOTAL AUDITORÍA | C32: Consolidado total de parámetros y presupuesto de implementación y operación | D32: =SUM(D28:D31) -> 19 | E32: =SUM(E28:E31) -> 1 | F32: =SUM(F28:F31) -> 26429700 | G32: Presupuesto 100% auditado y trazable con el alcance técnico del MVP
B34: 3. DECISIONES ESTRATÉGICAS DE DISEÑO PRESUPUESTAL Y MITIGACIÓN DE RIESGOS
B35: DEC-01: Auto-alojamiento en VPS vs SaaS Comercial | C35: Decisión de desplegar en un VPS Hetzner de 4GB ($12 USD/mes) en lugar de contratar un PMS comercial como Cloudbeds ($330 USD/mes). Genera un ahorro de $12.955.900 COP anuales y garantiza autonomía total sobre los datos de huéspedes y reservas.
B36: DEC-02: Doble Candado de Concurrencia (RedisLock + EXCLUDE GIST) | C36: Inversión en arquitectura de concurrencia en Sprint 1 para blindar las reservas. Evita indemnizaciones y pérdida de reputación por sobreventa en fechas de alta demanda en Sevilla (como las Fiestas del Café o Semana Santa).
B37: DEC-03: Chatbot n8n + Meta WhatsApp Cloud API vs Proveedores Intermediarios | C37: Conexión directa a la API de Meta utilizando los 1.000 mensajes mensuales gratuitos, en vez de plataformas intermediarias (como Trengo o ManyChat) que cobran tarifas mínimas de $90 USD/mes. Costo operativo mensual menor a $25.000 COP.
B38: DEC-04: Contratación por Hitos de Sprint Cerrados (30 SP / $4.200.000) | C38: Mecanismo de pago ligado a la aceptación formal de cada Sprint por parte del Product Owner contra la Definición de Hecho (DoD). Elimina el riesgo de sobrecostos por horas extras improductivas o desviación de alcance.
